Could not find R5 jar, trying to download it from upstream
Traceback (most recent call last):
  File "/home/ckboyd/.conda/envs/compute_ttm/lib/python3.11/site-packages/r5py/util/classpath.py", line 38, in <module>
    with open(R5_CLASSPATH, "rb") as jar:
         ^^^^^^^^^^^^^^^^^^^^^^^^
FileNotFoundError: [Errno 2] No such file or directory: '/home/ckboyd/.cache/r5py/r5-v6.6-all.jar'

During handling of the above exception, another exception occurred:

Traceback (most recent call last):
  File "/home/ckboyd/.conda/envs/compute_ttm/lib/python3.11/site-packages/urllib3/connection.py", line 200, in _new_conn
    sock = connection.create_connection(
           ^^^^^^^^^^^^^^^^^^^^^^^^^^^^^
  File "/home/ckboyd/.conda/envs/compute_ttm/lib/python3.11/site-packages/urllib3/util/connection.py", line 85, in create_connection
    raise err
  File "/home/ckboyd/.conda/envs/compute_ttm/lib/python3.11/site-packages/urllib3/util/connection.py", line 73, in create_connection
    sock.connect(sa)
TimeoutError: [Errno 110] Connection timed out

The above exception was the direct cause of the following exception:

Traceback (most recent call last):
  File "/home/ckboyd/.conda/envs/compute_ttm/lib/python3.11/site-packages/urllib3/connectionpool.py", line 790, in urlopen
    response = self._make_request(
               ^^^^^^^^^^^^^^^^^^^
  File "/home/ckboyd/.conda/envs/compute_ttm/lib/python3.11/site-packages/urllib3/connectionpool.py", line 491, in _make_request
    raise new_e
  File "/home/ckboyd/.conda/envs/compute_ttm/lib/python3.11/site-packages/urllib3/connectionpool.py", line 467, in _make_request
    self._validate_conn(conn)
  File "/home/ckboyd/.conda/envs/compute_ttm/lib/python3.11/site-packages/urllib3/connectionpool.py", line 1092, in _validate_conn
    conn.connect()
  File "/home/ckboyd/.conda/envs/compute_ttm/lib/python3.11/site-packages/urllib3/connection.py", line 604, in connect
    self.sock = sock = self._new_conn()
                       ^^^^^^^^^^^^^^^^
  File "/home/ckboyd/.conda/envs/compute_ttm/lib/python3.11/site-packages/urllib3/connection.py", line 209, in _new_conn
    raise ConnectTimeoutError(
urllib3.exceptions.ConnectTimeoutError: (<urllib3.connection.HTTPSConnection object at 0x7fe5954aafd0>, 'Connection to github.com timed out. (connect timeout=None)')

The above exception was the direct cause of the following exception:

Traceback (most recent call last):
  File "/home/ckboyd/.conda/envs/compute_ttm/lib/python3.11/site-packages/requests/adapters.py", line 486, in send
    resp = conn.urlopen(
           ^^^^^^^^^^^^^
  File "/home/ckboyd/.conda/envs/compute_ttm/lib/python3.11/site-packages/urllib3/connectionpool.py", line 844, in urlopen
    retries = retries.increment(
              ^^^^^^^^^^^^^^^^^^
  File "/home/ckboyd/.conda/envs/compute_ttm/lib/python3.11/site-packages/urllib3/util/retry.py", line 515, in increment
    raise MaxRetryError(_pool, url, reason) from reason  # type: ignore[arg-type]
    ^^^^^^^^^^^^^^^^^^^^^^^^^^^^^^^^^^^^^^^^^^^^^^^^^^^
urllib3.exceptions.MaxRetryError: HTTPSConnectionPool(host='github.com', port=443): Max retries exceeded with url: /conveyal/r5/releases/download/v6.6/r5-v6.6-all.jar (Caused by ConnectTimeoutError(<urllib3.connection.HTTPSConnection object at 0x7fe5954aafd0>, 'Connection to github.com timed out. (connect timeout=None)'))

During handling of the above exception, another exception occurred:

Traceback (most recent call last):
  File "/project/crberry/chicago-model-project/chicago-model/travel_time_matrix/compute_ttm.py", line 2, in <module>
    import r5py
  File "/home/ckboyd/.conda/envs/compute_ttm/lib/python3.11/site-packages/r5py/__init__.py", line 7, in <module>
    from .r5 import (
  File "/home/ckboyd/.conda/envs/compute_ttm/lib/python3.11/site-packages/r5py/r5/__init__.py", line 5, in <module>
    from .. import util  # noqa: F401
    ^^^^^^^^^^^^^^^^^^^
  File "/home/ckboyd/.conda/envs/compute_ttm/lib/python3.11/site-packages/r5py/util/__init__.py", line 5, in <module>
    from . import config, jvm, verbosity  # noqa: F401
    ^^^^^^^^^^^^^^^^^^^^^^^^^^^^^^^^^^^^
  File "/home/ckboyd/.conda/envs/compute_ttm/lib/python3.11/site-packages/r5py/util/jvm.py", line 8, in <module>
    from .classpath import R5_CLASSPATH
  File "/home/ckboyd/.conda/envs/compute_ttm/lib/python3.11/site-packages/r5py/util/classpath.py", line 49, in <module>
    with ValidatingRequestsSession() as session, session.get(
                                                 ^^^^^^^^^^^^
  File "/home/ckboyd/.conda/envs/compute_ttm/lib/python3.11/site-packages/r5py/util/validatingrequestssession.py", line 37, in get
    return self.request("GET", url, checksum, **kwargs)
           ^^^^^^^^^^^^^^^^^^^^^^^^^^^^^^^^^^^^^^^^^^^^
  File "/home/ckboyd/.conda/envs/compute_ttm/lib/python3.11/site-packages/r5py/util/validatingrequestssession.py", line 52, in request
    response = super().request(method, url, **kwargs)
               ^^^^^^^^^^^^^^^^^^^^^^^^^^^^^^^^^^^^^^
  File "/home/ckboyd/.conda/envs/compute_ttm/lib/python3.11/site-packages/requests/sessions.py", line 589, in request
    resp = self.send(prep, **send_kwargs)
           ^^^^^^^^^^^^^^^^^^^^^^^^^^^^^^
  File "/home/ckboyd/.conda/envs/compute_ttm/lib/python3.11/site-packages/requests/sessions.py", line 703, in send
    r = adapter.send(request, **kwargs)
        ^^^^^^^^^^^^^^^^^^^^^^^^^^^^^^^
  File "/home/ckboyd/.conda/envs/compute_ttm/lib/python3.11/site-packages/requests/adapters.py", line 507, in send
    raise ConnectTimeout(e, request=request)
requests.exceptions.ConnectTimeout: HTTPSConnectionPool(host='github.com', port=443): Max retries exceeded with url: /conveyal/r5/releases/download/v6.6/r5-v6.6-all.jar (Caused by ConnectTimeoutError(<urllib3.connection.HTTPSConnection object at 0x7fe5954aafd0>, 'Connection to github.com timed out. (connect timeout=None)'))
